Traceback (most recent call last):
  File "<string>", line 1, in <module>
    import dora; dora.start_runtime() # hand_rec
                 ~~~~~~~~~~~~~~~~~~^^
RuntimeError: Dora Runtime raised an error.

Caused by:
   0: main task failed
   1: operator hand_rec/op raised an error
   2: error in Python module at /Users/dave/dev/ultra/dora_webcam/hand_rec.py
   3: Traceback (most recent call last):
        File "/Users/dave/dev/ultra/dora_webcam/hand_rec.py", line 151, in on_event
landmarks.shape=torch.Size([0, 21, 3])
          batch = pa.Table.from_pydict({"hands": hands_data}, schema=schema)
flags=tensor([])
        File "pyarrow/table.pxi", line 1982, in pyarrow.lib._Tabular.from_pydict
landmarks.shape=torch.Size([1, 21, 3])
        File "pyarrow/table.pxi", line 6396, in pyarrow.lib._from_pydict
flags=tensor([0.0487], device='mps:0', grad_fn=<SigmoidBackward0>)
        File "pyarrow/array.pxi", line 405, in pyarrow.lib.asarray
        File "pyarrow/array.pxi", line 375, in pyarrow.lib.array
        File "pyarrow/array.pxi", line 45, in pyarrow.lib._sequence_to_array
        File "pyarrow/error.pxi", line 155, in pyarrow.lib.pyarrow_internal_check_status
        File "pyarrow/error.pxi", line 92, in pyarrow.lib.check_status

      ArrowTypeError: Could not convert {'box': [[96.8961410522461, 220.7340545654297, 182.90476989746094, 306.74267578125], [195.29991149902344, 281.30853271484375, 71.46199035644531, 157.4706268310547]], 'flag': 0.048727408051490784, 'handed': 0, 'normalized_landmarks': [[202.72607421875, 178.44491577148438, 2.3441098164767027e-05], [201.49002075195312, 194.57089233398438, -0.11470028758049011], [200.36138916015625, 204.08543395996094, -0.18878410756587982], [195.19851684570312, 204.7534942626953, -0.23575623333454132], [187.67776489257812, 204.29795837402344, -0.27303141355514526], [203.70477294921875, 196.94369506835938, -0.25653135776519775], [214.82859802246094, 194.6132354736328, -0.34475773572921753], [219.22036743164062, 196.70501708984375, -0.3909193277359009], [220.66310119628906, 199.109375, -0.4279642701148987], [206.54205322265625, 183.1632080078125, -0.22112691402435303], [213.60202026367188, 180.40493774414062, -0.2947346866130829], [219.78485107421875, 184.92234802246094, -0.3029686212539673], [223.16940307617188, 189.9337158203125, -0.31637126207351685], [207.16751098632812, 170.7897491455078, -0.1905469000339508], [215.60897827148438, 169.1341552734375, -0.25782865285873413], [222.535400390625, 173.76133728027344, -0.2589353024959564], [226.4815673828125, 179.5426788330078, -0.2598726153373718], [204.40231323242188, 159.7145538330078, -0.16879203915596008], [210.30715942382812, 157.26861572265625, -0.22239992022514343], [211.98727416992188, 157.57595825195312, -0.24489742517471313], [211.93829345703125, 159.50552368164062, -0.26488491892814636]]} with type dict: was not a sequence or recognized null for conversion to list type

Location:
    binaries/runtime/src/operator/python.rs:29:9
