Traceback (most recent call last):
  File "<string>", line 1, in <module>
    import dora; dora.start_runtime() # plot
                 ~~~~~~~~~~~~~~~~~~^^
RuntimeError: Dora Runtime raised an error.

Caused by:
   0: main task failed
   1: operator plot/op raised an error
   2: error in Python module at /Users/dave/dev/ultra/dora_webcam/plot.py
   3: Traceback (most recent call last):
        File "/Users/dave/dev/ultra/dora_webcam/plot.py", line 53, in on_event
[{'box': [[326.9788818359375, 240.784912109375, 379.42626953125, 293.2322998046875], [189.57034301757812, 242.01773071289062, 275.7643127441406, 328.2117004394531]], 'flag': 0.0062550208531320095, 'handed': 0, 'normalized_landmarks': [[285.2396545410156, 274.47589111328125, 2.1180370822548866e-05], [296.38031005859375, 268.02227783203125, 0.007044900208711624], [306.5675964355469, 261.3387451171875, 0.01024002954363823], [314.7088623046875, 256.6342468261719, 0.01371791772544384], [322.1911926269531, 252.7514190673828, 0.011995152570307255], [313.9146423339844, 258.61749267578125, -0.012991570867598057], [326.4802551269531, 251.7617645263672, -0.003514699637889862], [331.717529296875, 248.28282165527344, 0.009136654436588287], [334.506103515625, 245.68899536132812, 0.024090437218546867], [312.1481018066406, 258.1534729003906, -0.0053369998931884766], [325.6899719238281, 251.86898803710938, 0.0074932761490345], [329.934814453125, 248.70858764648438, 0.02189229242503643], [332.0620422363281, 247.19052124023438, 0.03330564498901367], [309.3935546875, 258.4263916015625, 0.005983555689454079], [320.88641357421875, 253.44168090820312, 0.01898624561727047], [323.8909912109375, 250.9307098388672, 0.03128543496131897], [324.58013916015625, 250.63958740234375, 0.04150852933526039], [306.13494873046875, 258.9573669433594, 0.018285779282450676], [315.83935546875, 255.5790557861328, 0.032592397183179855], [318.7470703125, 253.5548553466797, 0.04264155030250549], [319.5843200683594, 253.19224548339844, 0.0517808198928833]]}]
          draw_landmarks(image, landmarks[:,:2], HAND_CONNECTIONS, size=2)

      TypeError: list indices must be integers or slices, not tuple

Location:
    binaries/runtime/src/operator/python.rs:29:9
