Traceback (most recent call last):
  File "<string>", line 1, in <module>
    import dora; dora.start_runtime() # hand_rec
                 ~~~~~~~~~~~~~~~~~~^^
RuntimeError: Dora Runtime raised an error.

Caused by:
   0: main task failed
   1: operator hand_rec/op raised an error
   2: error in Python module at /Users/dave/dev/ultra/dora_webcam/hand_rec.py
   3: Traceback (most recent call last):
        File "/Users/dave/dev/ultra/dora_webcam/hand_rec.py", line 149, in on_event
landmarks.shape=torch.Size([0, 21, 3])
          batch = pa.Table.from_pydict({"hands": [hands_data]}, schema=schema)
flags=tensor([])
        File "pyarrow/table.pxi", line 1982, in pyarrow.lib._Tabular.from_pydict
landmarks.shape=torch.Size([1, 21, 3])
        File "pyarrow/table.pxi", line 6396, in pyarrow.lib._from_pydict
flags=tensor([0.0039], device='mps:0', grad_fn=<SigmoidBackward0>)
        File "pyarrow/array.pxi", line 405, in pyarrow.lib.asarray
        File "pyarrow/array.pxi", line 375, in pyarrow.lib.array
        File "pyarrow/array.pxi", line 45, in pyarrow.lib._sequence_to_array
        File "pyarrow/error.pxi", line 155, in pyarrow.lib.pyarrow_internal_check_status
        File "pyarrow/error.pxi", line 92, in pyarrow.lib.check_status

      ArrowInvalid: Length of item not correct: expected 4 but got array of size 2

Location:
    binaries/runtime/src/operator/python.rs:29:9
